Workbook

Sheet Dragon Kingdom CONDENSING
A1: ="Dragon Kingdom (total " & F22 & ")" -> Dragon Kingdom (total 22722)
A2: Dragon Village (needs access card) | E2: Crocovile Swamp (needs DJ) | I2: Dragonfly Falls (needs DJ + Glide + Ball Gadget)
A3: Description | B3: Amount | C3: Region Reqs | D3: Individual Reqs | E3: Description | F3: Amount | G3: Region Reqs | H3: Individual Reqs | I3: Description | J3: Amount | K3: Region Reqs | L3: Individual Reqs
A4: DVEntry | E4: CSEntry | I4: DFEntry
A5: Baskets behind chargeable wall by Elder | B5: 150 | C5: N/A | D5: Charge | E5: charge gates/walls | F5: 100 | G5: N/A | H5: Charge | I5: Chargeable wall immediates | J5: =250+899 -> 1149 | K5: N/A | L5: Charge
A6: Dark Shards | B6: 300 | C6: N/A | D6: Charge or DJ | E6: 5 Armored Chests (supercharge) | F6: 2550 | G6: N/A | H6: Charge + Supercharge | I6: 3 Goats | J6: 75 | K6: N/A | L6: FE
A7: Metal Chests | B7: 100 | C7: N/A | D7: E or Charge or DJ | E7: Crocoviles in E gate of temple | F7: =70+175 -> 245 | G7: N/A | H7: E | I7: Huge Gnorcs (armored) | J7: 100 | K7: N/A | L7: FE + Charge or I + Charge
A8: Baskets | B8: 175 | C8: N/A | D8: FEWI or Charge or DJ | E8: Armored Chest (firework in area after pyramid dark gem) | F8: 500 | G8: N/A | H8: F | I8: Plant + Huge Gnorcs (unarmored) | J8: 55 | K8: N/A | L8: FE or I + Charge
A9: Immediate (on ground) | B9: 336 | C9: N/A | D9: N/A | E9: Plants + Huge Gnorcs (unarmored) | F9: 161 | G9: N/A | H9: FE or I + Charge | I9: Crocoviles + Shepherd | J9: 395 | K9: N/A | L9: FE or Charge
A10: SUBTOTAL | C10: =SUM(B5:B9) -> 1061 | E10: Crocoviles + Critters | F10: =345+25 -> 370 | G10: N/A | H10: FE or Charge | I10: Spyro + Hunter immediates + ball gadget + sparx | J10: =5186+193 -> 5379 | K10: N/A | L10: N/A
A11: DVDoubleJump | E11: 2 Armored Chests on pyramid (cannon) | F11: 1000 | G11: N/A | H11: Glide | I11: Underwater in Piranha Area | J11: 100 | K11: Swim | L11: Charge
A12: Armored Chest before crocovile bridge (firework) | B12: 500 | C12: DJ | D12: F | E12: Blink + Breakables | F12: =953+1806 -> 2759 | G12: N/A | H12: N/A | I12: SUBTOTAL | K12: =SUM(J5:J11) -> 7253
A13: Huge gnorc (armored) above double jump ledge | B13: 20 | C13: DJ | D13: FE + Charge or I + Charge | E13: SUBTOTAL | G13: =SUM(F5:F12) -> 7685 | I13: DFLightGemDoor
A14: Huge gnorc (unarmored) in cave hunter pre-glide | B14: 20 | C14: DJ | D14: FE or I + Charge | E14: CSPoleSpin | I14: Huge Gnorcs (armored) | J14: 40 | K14: Light Gems | L14: FE + Charge or I + Charge
A15: On Ground hunter pre-glide | B15: =897+755 -> 1652 | C15: DJ | D15: N/A | E15: Armored Chest (firework at top of tree) in tree | F15: 500 | G15: Pole Spin | H15: F | I15: Huge Gnorcs (unarmored) | J15: 60 | K15: Light Gems | L15: FE or I + Charge
A16: SUBTOTAL | C16: =SUM(B12:B15) -> 2192 | D16: =C10+C16 -> 3253 | E16: Crocoviles | F16: 100 | G16: Pole Spin | H16: FE or Charge | I16: Blue Monkeys | J16: 75 | K16: Light Gems | L16: FE or Charge
A17: DVGlide | E17: Immediates | F17: 260 | G17: Pole Spin | H17: N/A | I17: Immediates | J17: =187+289 -> 476 | K17: Light Gems | L17: N/A
A18: Armored chests | B18: 1000 | C18: DJ + Glide | D18: F | E18: Armored Chest (firework at middle of tree) in tree | F18: 500 | G18: Pole Spin + Charge or Glide | H18: F | I18: SUBTOTAL | K18: =SUM(J14:J17) -> 651 | L18: =K12+K18 -> 7904
A19: Armored enemies | B19: 60 | C19: DJ + Glide | D19: FE + Charge or I + Charge | E19: SUBTOTAL | G19: =SUM(F15:F18) -> 1360 | H19: =G13+G19 -> 9045 | I19: DRAGONFLY FALLS TOTAL | J19: =SUM(J5:J18) -> 7904
A20: Huge Gnorcs (unarmored) | B20: 40 | C20: DJ + Glide | D20: FE or I + Charge | E20: SWAMP TOTAL | F20: =SUM(F5:F19) -> 9045
A21: Middle Gnorc (unarmored) in room | B21: 20 | C21: DJ + Glide | D21: FE or Charge | I21: missed 5 on test. Try again?
A22: Immediate (on ground + chests/baskets) ball gadget area | B22: =451+99 -> 550 | C22: DJ + Glide | D22: N/A | E22: DRAGON KINGDOM TOTAL | F22: =B29+F20+J19 -> 22722
A23: SUBTOTAL | C23: =SUM(B18:B22) -> 1670 | D23: =D16+C23 -> 4923
A24: DVCharge
A25: Immediate (on ground + baskets + chests) | B25: 310 | C25: DJ + Charge | D25: N/A
A26: 2 Gnorc Archers | B26: =4973-4933 -> 40 | C26: DJ + Charge | D26: FE or Charge
A27: armored chest (firework) in byrd area | B27: 500 | C27: DJ + Charge | D27: F + Glide
A28: SUBTOTAL | C28: =SUM(B25:B27) -> 850 | D28: =D23+C28 -> 5773
A29: DRAGON VILLAGE TOTAL | B29: =SUM(B2:B27) -> 5773

Sheet Lost Cities CONDENSING
A1: ="Lost Cities (total " & F29 & ")" -> Lost Cities (total 34648)
A2: Coastal Remains (requires access card) | E2: Cloudy Domain (requires DJ + Glide) | I2: Sunken Ruins (requires DJ + Pole Spin)
A3: Description | B3: Amount | C3: Region Reqs | D3: Individual Reqs | E3: Description | F3: Amount | G3: Region Reqs | H3: Individual Reqs | I3: Description | J3: Amount | K3: Region Reqs | L3: Individual Reqs
A4: CREntry | E4: CDEntry | I4: SREntry
A5: Headbash Crates | B5: 200 | C5: N/A | D5: DJ | E5: Middle Gnorcs (flying) + Small Gnorcs (flying) | F5: 125 | G5: N/A | H5: FE | I5: On ground + chests + baskets + shards | J5: 240 | K5: N/A | L5: N/A
A6: Metal Crates | B6: =350-75 -> 275 | C6: N/A | D6: E or Charge or DJ | E6: Middle Gnorcs (armored) | F6: 20 | G6: N/A | H6: Charge | I6: Critters, Mer-Gnorc | J6: 125 | K6: N/A | L6: FE or Charge
A7: Large blue crabs | B7: 175 | C7: N/A | D7: E or I + Charge or Charge + DJ | E7: Huge Gnorcs (unarmored) | F7: 80 | G7: N/A | H7: FE or I + Charge | I7: SUBTOTAL | K7: =J5+J6 -> 365
A8: Huge Gnorcs (armored) | B8: 60 | C8: N/A | D8: FE + Charge or I + Charge | E8: On ground + baskets + chests + dark shards | F8: 507 | G8: N/A | H8: N/A | I8: SRSwim
A9: Huge Gnorc (unarmored) on way to Otto's pool | B9: 20 | C9: N/A | D9: FE or I + Charge | E9: SUBTOTAL | G9: =SUM(F5:F8) -> 732 | I9: Underwater breakable stuff | J9: =225+250 -> 475 | K9: Swim | L9: Charge
A10: Middle Gnorcs (unarmored) + Critters + Pygmy Cannibals + orange crabs | B10: =765-175 -> 590 | C10: N/A | D10: FE or Charge | E10: CDCharge | I10: after second swim Blue Crabs | J10: 50 | K10: Swim | L10: E or I + Charge or Charge + DJ
A11: Baskets | B11: 750 | C11: N/A | D11: FEWI or Charge or DJ | E11: Armored Chest (firework right before light gem) | F11: 500 | G11: Charge | H11: F | I11: Mer-gnorc, critters | J11: 125 | K11: Swim | L11: FE or Charge
A12: On ground | B12: 722 | C12: N/A | D12: N/A | E12: Middle Gnorcs (flying) + Small Gnorcs (flying) | F12: 125 | G12: Charge | H12: FE | I12: Immediates | J12: =2588+2148 -> 4736 | K12: Swim | L12: N/A
A13: Underwater stuff | B13: 650 | C13: Swim | D13: Charge | E13: Huge Gnorcs (armored) | F13: 20 | G13: Charge | H13: FE + Charge or I + Charge | I13: after first swim Armored Chests (firework up the whirlwinds) | J13: 1500 | K13: Swim + Glide | L13: F
A14: SUBTOTAL | C14: =SUM(B5:B13) -> 3442 | E14: Huge Gnorc (unarmored) | F14: 20 | G14: Charge | H14: FE or I + Charge | I14: after first swim Immediates up the whirlwinds | J14: 397 | K14: Swim + Glide | L14: N/A
A15: CRDoubleJump | E15: Immediates | F15: 730 | G15: Charge | H15: N/A | I15: after second swim Chest + Basket near light gem after invince section | J15: 50 | K15: Swim + Invincibility | L15: N/A
A16: Pygmies | B16: 50 | C16: DJ | D16: FE or Charge | E16: Supercharge stuff | F16: 1575 | G16: Charge + Supercharge | H16: N/A | I16: SUBTOTAL | K16: =SUM(J9:J15) -> 7333 | L16: =K7+K16 -> 7698
A17: pole spin area Huge Gnorc (unarmored) by Dark Gem | B17: 20 | C17: DJ | D17: FE or I + Charge | E17: SUBTOTAL | G17: =SUM(F11:F16) -> 2970 | H17: =G9+G17 -> 3702 | I17: SRWallKick
A18: piranha pool + windmill area immediates | B18: =148+525 -> 673 | C18: DJ | D18: N/A | E18: CDWingShield | I18: invince wall kick 3 Armored Chests further below (firework up high) | J18: 1500 | K18: Swim + Wall Kick + Invincibility | L18: F
A19: SUBTOTAL | C19: =SUM(B16:B18) -> 743 | D19: =C14+C19 -> 4185 | E19: Small Gnorcs (flying) | F19: 475 | G19: Charge + Wing Shield | H19: FE | I19: invince wall kick Mer-gnorcs | J19: 50 | K19: Swim + Wall Kick + Invincibility | L19: FE or Charge
A20: CRLightGemDoor | E20: Huge Gnorc (unarmored) | F20: 40 | G20: Charge + Wing Shield | H20: FE or I + Charge | I20: SUBTOTAL | K20: =J18+J19 -> 1550 | L20: =L16+K20 -> 9248
A21: Headbash Crates | B21: 50 | C21: Light Gems | D21: DJ | E21: Immediates + Byrd | F21: 1625 | G21: Charge + Wing Shield | H21: N/A | I21: SRElectric
A22: Metal Crates | B22: 50 | C22: Light Gems | D22: E or Charge or DJ | E22: SUBTOTAL | G22: =SUM(F19:F21) -> 2140 | H22: =H17+G22 -> 5842 | I22: Immediate | J22: 606 | K22: Swim + E | L22: N/A
A23: Huge Gnorcs (armored) | B23: 20 | C23: Light Gems | D23: FE + Charge or I + Charge | E23: CDBallGadget | I23: Dark Shards above Invince | J23: 150 | K23: Swim + E + Glide | L23: N/A
A24: Gnorc Archers + Middle Gnorcs (unarmored) | B24: 40 | C24: Light Gems | D24: FE or Charge | E24: Ball Gadget | F24: =715+100 -> 815 | G24: Charge + Wing Shield + Ball Gadget | H24: N/A | I24: SUBTOTAL | K24: =J22+J23 -> 756 | L24: =L16+K24 -> 8454
A25: Baskets | B25: 125 | C25: Light Gems | D25: FEWI or Charge or DJ | E25: Armored Chest at start (firework post-ball gadget) | F25: 500 | G25: Charge + Wing Shield + Ball Gadget | H25: F | I25: SRInvincibility
A26: On Ground | B26: 239 | C26: Light Gems | D26: N/A | E26: SUBTOTAL | G26: =SUM(F24:F25) -> 1315 | H26: =H22+G26 -> 7157 | I26: Immediate | J26: =540+1701 -> 2241 | K26: Swim + E + Invince + Charge | L26: N/A
A27: Huge Gnorc (armored) up high | B27: 20 | C27: Light Gems + DJ | D27: FE + Charge or I + Charge | E27: CLOUDY DOMAIN TOTAL | F27: =SUM(F5:F26) -> 7157 | I27: 3 Armored Chests below (firework after dark gem) | J27: 1500 | K27: Swim + E + Invince + Charge | L27: F
A28: Gnorc Archers up high | B28: 40 | C28: Light Gems + DJ | D28: FE or Charge | I28: SUBTOTAL | K28: =SUM(J26:J27) -> 3741 | L28: =L24+K28 -> 12195
A29: Immediate (baskets + crates up high) | B29: 125 | C29: Light Gems + DJ | D29: N/A | E29: LOST CITIES TOTAL | F29: =B48+F27+J32 -> 34648 | I29: SRGlide
A30: SUBTOTAL | C30: =SUM(B21:B29) -> 709 | D30: =D19+C30 -> 4894 | I30: Immediates (including gliding above swim rooms) | J30: =208+692 -> 900 | K30: Swim + E + Invince + Charge + Glide | L30: N/A
A31: CRGlide | I31: SUBTOTAL | K31: =J30 -> 900 | L31: =L28+K31 -> 13095
A32: Huge Gnorc (armored) | B32: 20 | C32: DJ + Glide | D32: FE + Charge or I + Charge | I32: SUNKEN RUINS TOTAL | J32: =SUM(J5:J31) -> 14645
A33: Immediates + in otto's pool + Blink | B33: 2070 | C33: DJ + Glide | D33: N/A | F33: sunken ruins has 14,645
A34: Huge Gnorc (armored) after Electric Platform near cloudy | B34: 20 | C34: DJ + Glide + E | D34: F + Charge or I + Charge
A35: Immediate after Electric Platform near cloudy | B35: 493 | C35: DJ + Glide + E | D35: N/A
A36: pole spin area stuff by egg | B36: 1050 | C36: DJ + Glide + Pole Spin | D36: N/A
A37: SUBTOTAL | C37: =SUM(B32:B36) -> 3653 | D37: =D30+C37 -> 8547
A38: CRSunkenEntrance
A39: Huge Gnorc (armored) | B39: 20 | C39: DJ + Pole Spin | D39: FE + Charge or I + Charge
A40: Huge Gnorcs (unarmored) | B40: 40 | C40: DJ + Pole Spin | D40: FE or I + Charge
...

Sheet Icy Wilderness CONDENSING
A1: ="Icy Wilderness (total " & F9 & ")" -> Icy Wilderness (total 35781)
A2: Frostbite Village (requires access card, later on requires return via Gloomy Glacier) | E2: Gloomy Glacier (requires DJ) | I2: Ice Citadel (requires DJ)
A3: Description | B3: Amount | C3: Region Reqs | D3: Individual Reqs | E3: Description | F3: Amount | G3: Region Reqs | H3: Individual Reqs | I3: Description | J3: Amount | K3: Region Reqs | L3: Individual Reqs
A4: FVEntry | E4: GGEntry | I4: ICEntry
A5: Baskets | B5: 25 | C5: N/A | D5: FEWI or Charge or DJ | E5: Everything lol | F5: 5631 | G5: N/A | H5: N/A | I5: Middle gnorcs (armored) | J5: 80 | K5: N/A | L5: Charge
A6: Headbash Crates | B6: 80 | C6: N/A | D6: DJ | E6: SUBTOTAL | G6: =SUM(F5:F5) -> 5631 | I6: Steel Traps | J6: 200 | K6: N/A | L6: E or I + Charge
A7: SUBTOTAL | C7: =B5+B6 -> 105 | E7: GLOOMY GLACIER TOTAL | F7: =SUM(F5:F6) -> 5631 | I7: Firework chest + 3 Armored chests (firework by water wheel) | J7: 1525 | K7: N/A | L7: F
A8: FVEletric | I8: Huge Gnorcs (armored) | J8: 20 | K8: N/A | L8: FE + Charge or I + Charge
A9: Immediate | B9: 415 | C9: E | D9: N/A | E9: ICY WILDERNESS TOTAL | F9: =B45+F7+J37 -> 35781 | I9: Middle gnorcs (unarmored) + Gnorc Archers | J9: 180 | K9: N/A | L9: FE or Charge
A10: Immediate (near light gem after floating platform) | B10: 130 | C10: EW + DJ | D10: N/A | I10: 3 Baskets you can't DJ to break | J10: 75 | K10: N/A | L10: FEWI or Charge
A11: Eskimole under snowman | B11: 25 | C11: DJ | D11: N/A | I11: Immediate | J11: 1073 | K11: N/A | L11: N/A
A12: SUBTOTAL | C12: =SUM(B9:B11) -> 570 | D12: =C7+C12 -> 675 | I12: SUBTOTAL | K12: =SUM(J5:J11) -> 3153
A13: FVDoubleJump | I13: ICWater
A14: Huge Gnorc (armored) | B14: 100 | C14: DJ | D14: FE + Charge or I + Charge | I14: Steel Traps | J14: 400 | K14: W | L14: E or I + Charge
A15: Middle Gnorcs (armored) | B15: 40 | C15: DJ | D15: Charge | I15: Huge Gnorcs (armored) | J15: 20 | K15: W | L15: FE + Charge or I + Charge
A16: Eskimoles + middle gnorcs (unarmored) | B16: =210+20 -> 230 | C16: DJ | D16: FE or Charge | I16: Middle gnorcs (armored) + headbash behind chargeable wall | J16: 45 | K16: W | L16: Charge
A17: Baskets on Ice | B17: 50 | C17: DJ | D17: FEWI or Charge | I17: Yeti + Middle gnorcs (unarmored) | J17: 60 | K17: W | L17: FE or Charge
A18: Immediates + Blink | B18: =3837+1036 -> 4873 | C18: DJ | D18: N/A | I18: Immediate | J18: 683 | K18: W | L18: N/A
A19: SUBTOTAL | C19: =SUM(B14:B18) -> 5293 | D19: =D12+C19 -> 5968 | I19: SUBTOTAL | K19: =SUM(J14:J18) -> 1208 | L19: =K12+K19 -> 4361
A20: FVWallKick | I20: ICWallKick
A21: Huge Gnorc (armored) | B21: 20 | C21: DJ + Wall Kick | D21: FE + Charge or I + Charge | I21: Steel Traps | J21: 225 | K21: W + Wall Kick | L21: E or I + Charge
A22: Middle Gnorc (unarmored) | B22: 20 | C22: DJ + Wall Kick | D22: FE or Charge | I22: Firework chest | J22: 50 | K22: W + Wall Kick | L22: F
A23: Immediate (on ground + baskets + chests) | B23: 271 | C23: DJ + Wall Kick | D23: N/A | I23: Ice Monster | J23: =59871-59846 -> 25 | K23: W + Wall Kick | L23: FE
A24: gems behind chargeable wall | B24: 11 | C24: DJ + Wall Kick + Charge | D24: N/A | I24: Huge Gnorc (armored) | J24: 80 | K24: W + Wall Kick | L24: FE + Charge or I + Charge
A25: Eskimole on the small platform thing | B25: 25 | C25: DJ + Wall Kick + Glide | D25: FE or Charge | I25: Huge Gnorc (unarmored) | J25: 20 | K25: W + Wall Kick | L25: FE or I + Charge
A26: immediate beyond big cannon ball thing | B26: 630 | C26: DJ + Wall Kick + Glide | D26: N/A | I26: Gnorc Archer | J26: 241 | K26: W + Wall Kick | L26: FE or Charge
A27: SUBTOTAL | C27: =SUM(B21:B26) -> 977 | D27: =D19+C27 -> 6945 | I27: Immediates + Byrd | J27: =7075+1630 -> 8705 | K27: W + Wall Kick | L27: N/A
A28: =_xlfn._LONGTEXT("---------------------------------------------------------------------------------------------------------------------------------------------------------------------------------------------------------------------------------------------------------------","-----------------------------------------") -> -------------------------------------------------------------------------------------------------------------------------------------------------------------------------------------------------------------------------------------------------------------------------------------------------------- | I28: Supercharge stuff | J28: =1500+615 -> 2115 | K28: W + Wall Kick | L28: Charge + Supercharge
A29: FVEntry2 | I29: SUBTOTAL | K29: =SUM(J21:J28) -> 11461 | L29: =L19+K29 -> 15822
A30: Huge gnorc (armored) | B30: 20 | C30: DJ + W + Wall Kick + Charge + Supercharge | D30: FE or I | I30: ICBehindQueen
A31: Immediates + armored chests | B31: =1553+175 -> 1728 | C31: DJ + W + Wall Kick + Charge + Supercharge | D31: N/A | I31: Huge Gnorc (armored) | J31: 20 | K31: W + Wall Kick + E + Pole Spin + Glide | L31: FE + Charge or I + Charge
A32: SUBTOTAL | C32: =SUM(B30:B31) -> 1748 | I32: Gnorc Archer | J32: 60 | K32: W + Wall Kick + E + Pole Spin + Glide | L32: FE or Charge
A33: FVEastPoles | I33: SUBTOTAL | K33: =J31+J32 -> 80 | L33: =L29+K33 -> 15902
A34: Huge gnorcs | B34: 40 | C34: DJ + W + Wall Kick + Supercharge + Pole Spin | D34: FE or I | I34: ICReturnToFV
A35: SUBTOTAL | C35: =B34 -> 40 | D35: =C32+C35 -> 1788 | I35: Immediates (9 armored chests) | J35: =73352-68852 -> 4500 | K35: W + Wall Kick + Supercharge | L35: N/A
A36: FVLGDoorEntry | I36: SUBTOTAL | K36: =J35+L33 -> 20402
A37: Immediates | B37: 180 | C37: DJ + W + Wall Kick + Charge + Supercharge + Light Gems | D37: N/A | I37: ICE CITADEL TOTAL | J37: =SUM(J5:J35) -> 20402
A38: Huge gnorcs | B38: 40 | C38: DJ + W + Wall Kick + Charge + Supercharge + Light Gems | D38: FE or I
A39: Immediates past pole spin | B39: 200 | C39: DJ + W + Wall Kick + Charge + Supercharge + Light Gems + Pole Spin | D39: N/A
A40: SUBTOTAL | C40: =SUM(B37:B39) -> 420 | D40: =D35+C40 -> 2208
...

Sheet Volcanic Isle CONDENSING
A1: ="Volcanic Isle (total " & F27 & ")" -> Volcanic Isle (total 49306)
A2: Stormy Beach (requires access card) | E2: Molten Mount (requires DJ + Glide) | I2: Magma Falls (requires DJ + Glide + WI + Pole Spin + Wall Kick) | M2: Dark Mine (requires DJ + Glide + WI + Pole Spin + Wall Kick + Ball Gadget) | Q2: Red's Lab (needs DJ + Glide + WI + Pole Spin + Wall Kick + Ball Gadget + charge + E + Ice)
A3: Description | B3: Amount | C3: Region Reqs | D3: Individual Reqs | E3: Description | F3: Amount | G3: Region Reqs | H3: Individual Reqs | I3: Description | J3: Amount | K3: Region Reqs | L3: Individual Reqs | M3: Description | N3: Amount | O3: Region Reqs | P3: Individual Reqs | Q3: Description | R3: Amount | S3: Region Reqs | T3: Individual Reqs
A4: SBEntry | E4: MMEntry | I4: MFtEntry | M4: DMEntry | Q4: RLEntry
A5: Middle gnorcs (armored) | B5: 80 | C5: N/A | D5: Charge | E5: Steel traps | F5: 50 | G5: N/A | H5: E or I + Charge | I5: Firework chest (behind chargeable thing) | J5: 25 | K5: Charge | L5: F | M5: Immediates behind chargeable wall things | N5: 100 | O5: N/A | P5: Charge | Q5: Immediates | R5: 1083 | S5: N/A | T5: N/A
A6: Dark Shards | B6: 350 | C6: N/A | D6: Charge or DJ | E6: Armored chest near start (firework) | F6: 500 | G6: N/A | H6: F | I6: Huge gnorc (armored) behind chargeable thing by moneybags | J6: 20 | K6: Charge | L6: FE + Charge or I + Charge | M6: Haywire Robots (Drill) | N6: 60 | O6: N/A | P6: E or Charge | Q6: SUBTOTAL | S6: =R5 -> 1083
A7: Headbash Chest | B7: 30 | C7: N/A | D7: DJ | E7: Immediate | F7: 572 | G7: N/A | H7: N/A | I7: Chargeable things | J7: 200 | K7: Charge | L7: N/A | M7: Spike robots + steel traps | N7: 150 | O7: N/A | P7: E or I + Charge | Q7: RLSouthEast
A8: Metal Chests | B8: 300 | C8: N/A | D8: E or Charge or DJ | E8: Armored chests near start (supercharge) | F8: 1500 | G8: N/A | H8: Supercharge | I8: Firework chest + armored chest | J8: 525 | K8: F | L8: N/A | M8: Critters | N8: 75 | O8: N/A | P8: FE or Charge | Q8: Immediates | R8: 680 | S8: N/A | T8: N/A
A9: Steel Traps | B9: 375 | C9: N/A | D9: E or I + Charge | E9: SUBTOTAL | G9: =SUM(F5:F8) -> 2622 | I9: Huge gnorcs (armored) by ball gadget | J9: 40 | K9: FE + Charge or I + Charge | L9: N/A | M9: Immediates | N9: =690+50 -> 740 | O9: N/A | P9: N/A | Q9: Immediates above furnace | R9: 70 | S9: F | T9: N/A
A10: 2 Armored Chests (firework on the ship) | B10: 1000 | C10: N/A | D10: F | E10: MMWaterIce | I10: Middle gnorc (unarmored) | J10: 20 | K10: FE or Charge | L10: N/A | M10: SUBTOTAL | O10: =SUM(N5:N9) -> 1125 | Q10: SUBTOTAL | S10: =R8+R9 -> 750 | T10: =S6+S10 -> 1833
A11: Huge Gnorcs (armored) | B11: 60 | C11: N/A | D11: FE + Charge or I + Charge | E11: Rock Monsters | F11: 400 | G11: WI | H11: Charge | I11: Immediate | J11: =695+75 -> 770 | K11: N/A | L11: N/A | M11: DMLightGemDoor | Q11: RLNorthWest
A12: Middle Gnorcs (unarmored) | B12: 140 | C12: N/A | D12: FE or Charge | E12: initial gliding Firework Chest | F12: 25 | G12: WI | H12: F | I12: SUBTOTAL | K12: =SUM(J5:J11) -> 1600 | M12: Huge robo-gnorcs + steel traps | N12: =470+50 -> 520 | O12: Light Gems | P12: E or I + Charge | Q12: Immediates | R12: 1119 | S12: N/A | T12: N/A
A13: Baskets | B13: 350 | C13: N/A | D13: FEWI or Charge or DJ | E13: Huge gnorcs (armored) | F13: 40 | G13: WI | H13: FE + Charge or I + Charge | I13: MFBallGadget | M13: Critters | N13: 125 | O13: Light Gems | P13: FE or Charge | Q13: SUBTOTAL | S13: =R12 -> 1119 | T13: =T10+S13 -> 2952
A14: On ground | B14: 263 | C14: N/A | D14: N/A | E14: middle gnorcs (unarmored) | F14: 20 | G14: WI | H14: FE or Charge | I14: Immediates | J14: 447 | K14: Ball Gadget | L14: N/A | M14: Invince swimming (chests) | N14: 350 | O14: Light Gems + Invince + Swim | P14: Charge | Q14: RLNorthEast
A15: Underwater vases by realm portal | B15: 100 | C15: Swim | D15: Charge | E15: Huge gnorcs (unarmored) | F15: 20 | G15: WI | H15: FE or I + Charge | I15: SUBTOTAL | K15: =J14 -> 447 | L15: =K12+K15 -> 2047 | M15: SUBTOTAL | O15: =SUM(N12:N14) -> 995 | P15: =O10+O15 -> 2120 | Q15: Immediates | R15: =109265-108705 -> 560 | S15: N/A | T15: N/A
A16: SUBTOTAL | C16: =SUM(B5:B15) -> 3048 | E16: Immediates + Byrd | F16: =886+1729 -> 2615 | G16: WI | H16: N/A | I16: MFbEntry | M16: DMCharge | Q16: Immediates via invince | R16: 155 | S16: Invincibility | T16: N/A
A17: SBDoubleJump | E17: SUBTOTAL | G17: =SUM(F11:F16) -> 3120 | H17: =G9+G17 -> 5742 | I17: Huge gnorc (armored) | J17: 40 | K17: Ball Gadget | L17: FE + Charge or I + Charge | M17: Huge robo-gnorcs | N17: 20 | O17: Charge | P17: E or I + Charge | Q17: SUBTOTAL | S17: =R15+R16 -> 715 | T17: =T13+S17 -> 3667
A18: Middle gnorc (armored) | B18: 20 | C18: DJ | D18: Charge | E18: MMPoleSpin | I18: Middle gnorc (unarmored) | J18: 60 | K18: Ball Gadget | L18: FE or Charge | M18: 3 armored chests (firework) | N18: 1500 | O18: Charge | P18: F | Q18: RLSouthWest
A19: Armored chests | B19: 2500 | C19: DJ | D19: F | E19: behind chargeable walls + middle armored gnorcs | F19: =890+40 -> 930 | G19: WI + Pole Spin | H19: Charge | I19: Immediates + Sparx | J19: =1101+2389 -> 3490 | K19: Ball Gadget | L19: N/A | M19: Immediate | N19: 550 | O19: Charge | P19: N/A | Q19: Immediates | R19: 140
A20: Huge Gnorcs (armored) | B20: 20 | C20: DJ | D20: FE + Charge or I + Charge | E20: Huge gnorc (armored) | F20: 60 | G20: WI + Pole Spin | H20: FE + Charge or I + Charge | I20: Chargeable wall things | J20: =336+60 -> 396 | K20: Ball Gadget | L20: Charge | M20: Immediates up wall kick pistons | N20: 70 | O20: Charge + Wall Kick | P20: N/A | Q20: SUBTOTAL | S20: =R19 -> 140 | T20: =T17+S20 -> 3807
A21: Gnorc archers + middle gnorcs (unarmored) | B21: 40 | C21: DJ | D21: FE or Charge | E21: Middle gnorc (unarmored) | F21: 260 | G21: WI + Pole Spin | H21: FE or Charge | I21: SUBTOTAL | K21: =SUM(J17:J20) -> 3986 | L21: =L15+K21 -> 6033 | M21: SUBTOTAL | O21: =SUM(N17:N20) -> 2140 | P21: =P15+O21 -> 4260 | Q21: RED'S LAB TOTAL | R21: =SUM(R5:R19) -> 3807
A22: Immediate | B22: =1334+80 -> 1414 | C22: DJ | D22: N/A | E22: headbash rock thing under huge gnorc (unarmored) | F22: 25 | G22: WI + Pole Spin | H22: FE or I + Charge | I22: MAGMA FALLS TOTAL | J22: =SUM(J5:J21) -> 6033 | M22: DMElectric
A23: SUBTOTAL | C23: =SUM(B18:B22) -> 3994 | D23: =C16+C23 -> 7042 | E23: Immediates | F23: =5131+25 -> 5156 | G23: WI + Pole Spin | H23: N/A | M23: Immediates | N23: =12220+1240 -> 13460 | O23: Charge + E | P23: N/A
A24: SBUpperCave | E24: SUBTOTAL | G24: =SUM(F19:F23) -> 6431 | H24: =H17+G24 -> 12173 | M24: SUBTOTAL | O24: =N23 -> 13460 | P24: =P21+O24 -> 17720
A25: Gnorc archers by chest | B25: 40 | C25: DJ + Wall Kick + Glide | D25: FE or Charge | E25: MOLTEN MOUNT TOTAL | F25: =SUM(F5:F23) -> 12173 | M25: DMIce
A26: Immediate | B26: 60 | C26: DJ + Wall Kick + Glide | D26: N/A | M26: Immediates | N26: =795+136 -> 931 | O26: Charge + E + Ice
A27: SUBTOTAL | C27: =B25+B26 -> 100 | D27: =D23+C27 -> 7142 | E27: VOLCANIC ISLE TOTAL | F27: =B28+F25+J22+N29+R21 -> 49306 | M27: 3 armored chests by start (firework after ice and pole spin) | N27: 1500 | O27: Charge + E + Ice | P27: F
A28: STORMY BEACH TOTAL | B28: =SUM(B5:B26) -> 7142 | M28: SUBTOTAL | O28: =N26+N27 -> 2431 | P28: =P24+O28 -> 20151
E29: GAME TOTAL | F29: ='Dragon Kingdom'!F36+'Lost Cities'!F32+'Icy Wilderness'!F16+'Volcanic Isle CONDENSING'!F27 -> 139488 | M29: DARK MINE TOTAL | N29: =SUM(N4:N28) -> 20151

Sheet Dragon Kingdom EDITING
A1: ="Dragon Kingdom (total " & F32 & ")" -> Dragon Kingdom (total 22722)
A2: Dragon Village (needs access card) | E2: Crocovile Swamp (needs DJ) | I2: Dragonfly Falls (needs DJ + Glide + Ball Gadget)
A3: Description | B3: Amount | C3: Region Reqs | D3: Individual Reqs | E3: Description | F3: Amount | G3: Region Reqs | H3: Individual Reqs | I3: Description | J3: Amount | K3: Region Reqs | L3: Individual Reqs
A4: DVEntry | E4: CSEntry | I4: DFEntry
A5: Immediate (on ground) | B5: 336 | C5: N/A | D5: None | E5: Immediate (on ground + chests + baskets + dark shards) | F5: 873 | G5: N/A | H5: N/A | I5: Ball Gadget Path | J5: 896 | K5: N/A | L5: N/A
A6: Baskets | B6: 175 | C6: N/A | D6: FEWI or Charge or DJ | E6: Crocoviles + Critters | F6: 345 | G6: N/A | H6: FE or I + Charge or Charge | I6: Crocoviles + Shepherd | J6: 395 | K6: N/A | L6: FE or I + Charge or Charge
A7: Metal Chests | B7: 100 | C7: N/A | D7: E or Charge or DJ | E7: Plants + Huge Gnorcs (unarmored) | F7: 161 | G7: N/A | H7: FE or I + Charge | I7: Immediate (on ground + Chests + Baskets) | J7: 1511 | K7: N/A | L7: N/A
A8: Dark Shards | B8: 300 | C8: N/A | D8: Charge or DJ | E8: 3 Baskets behind chargeable thing | F8: 75 | G8: Charge | H8: N/A | I8: 3 Goats | J8: 75 | K8: N/A | L8: FE
A9: Baskets behind chargeable wall by Elder | B9: 150 | C9: Charge | D9: N/A | E9: Metal Chest behind chargeable thing in Elder's tree | F9: 25 | G9: Charge | H9: N/A | I9: Plant + Huge Gnorcs (unarmored) | J9: 55 | K9: N/A | L9: FE or I + Charge
A10: SUBTOTAL | C10: =SUM(B5:B9) -> 1061 | E10: 2 Armored Chests on pyramid (cannon) | F10: 1000 | G10: N/A | H10: Glide | I10: Huge Gnorcs (armored) | J10: 100 | K10: N/A | L10: FE + Charge or I + Charge
A11: DVDoubleJump | E11: 5 Armored Chests (supercharge) | F11: 2500 | G11: N/A | H11: Supercharge | I11: Underwater in Piranha Area | J11: 100 | K11: Swim | L11: Charge
A12: On Ground hunter pre-glide | B12: 31 | C12: DJ | D12: N/A | E12: 2 metal chests behind supercharge door | F12: 50 | G12: Charge + Supercharge | H12: N/A | I12: 5 Dark Shards behind chargeable wall with dark gem | J12: 250 | K12: Charge | L12: N/A
A13: Chests/Baskets hunter pre-glide | B13: 255 | C13: DJ | D13: N/A | E13: Armored Chest (firework in area after pyramid dark gem) | F13: 500 | G13: N/A | H13: F | I13: Chests + Baskets behind chargeable walls | J13: 899 | K13: Charge | L13: N/A
A14: Huge gnorc (armored) above double jump ledge | B14: 20 | C14: DJ | D14: FE + Charge or I + Charge | E14: Crocovile in forgotten temple | F14: 25 | G14: N/A | H14: FE or I + Charge or Charge | I14: Hunter Immediate (almost everything) | J14: =1166+90 -> 1256 | K14: N/A | L14: N/A
A15: Huge gnorc (unarmored) in cave hunter pre-glide | B15: 20 | C15: DJ | D15: FE or I + Charge | E15: Baskets + Chests behind gate in temple | F15: 80 | G15: N/A | H15: N/A | I15: Hunter Behind first explode-y arrow wall | J15: 143 | K15: N/A | L15: 1 Explosive Arrow
A16: Armored Chest before crocovile bridge (firework) | B16: 500 | C16: DJ | D16: F | E16: Crocoviles in E gate of temple | F16: 70 | G16: E | H16: FE or I + Charge or Charge | I16: Hunter 2 Metal chests in distance | J16: 50 | K16: N/A | L16: 1 Explosive Arrow
A17: Immediate post-crocovile bridge (on ground + baskets) | B17: 215 | C17: DJ | D17: N/A | E17: Chests + Baskets in E gate of temple | F17: 175 | G17: E | H17: N/A | I17: Sparx 1 | J17: 695 | K17: N/A | L17: N/A
A18: Immediates post-double jump ledge | B18: 396 | C18: DJ | D18: N/A | E18: Blink 1 | F18: 928 | G18: N/A | H18: N/A | I18: Sparx 2 | J18: 828 | K18: N/A | L18: N/A
A19: Byrd 1 | B19: 395 | C19: DJ | D19: N/A | E19: Blink 2 | F19: 878 | G19: N/A | H19: N/A | I19: SUBTOTAL | K19: =SUM(J5:J18) -> 7253
A20: Byrd 2 | B20: 360 | C20: DJ | D20: N/A | E20: SUBTOTAL | G20: =SUM(F5:F19) -> 7685 | I20: DFLightGemDoor
A21: SUBTOTAL | C21: =SUM(B12:B20) -> 2192 | D21: =C10+C21 -> 3253 | E21: CSPoleSpin | I21: Immediate (on ground + chests + baskets) | J21: 289 | K21: Light Gems | L21: N/A
A22: DVGlide | E22: Baskets + Chests in tree | F22: 160 | G22: Pole Spin | H22: N/A | I22: Huge Gnorcs (unarmored) | J22: 60 | K22: Light Gems | L22: FE or I + Charge
A23: Immediate (on ground + chests/baskets) | B23: 451 | C23: DJ + Glide | D23: N/A | E23: Crocovile in tree | F23: 25 | G23: Pole Spin | H23: FE or I + Charge or Charge | I23: Huge Gnorcs (armored) | J23: 40 | K23: Light Gems | L23: FE + Charge or I + Charge
A24: Middle Gnorc (unarmored) in room | B24: 20 | C24: DJ + Glide | D24: FE or I + Charge or Charge | E24: Armored Chest (firework at top of tree) in tree | F24: 500 | G24: Pole Spin | H24: F | I24: Blue Monkeys | J24: 75 | K24: Light Gems | L24: FE or I + Charge or Charge
A25: Huge Gnorcs (unarmored) | B25: 40 | C25: DJ + Glide | D25: FE or I + Charge | E25: Armored Chest (firework at middle of tree) in tree | F25: 500 | G25: Pole Spin + Charge or Glide | H25: F | I25: Below whirlwind behind chargeable wall | J25: 187 | K25: Light Gems | L25: N/A
A26: Huge Gnorc (armored) in cave | B26: 20 | C26: DJ + Glide | D26: FE + Charge or I + Charge | E26: Crocoviles in cave away from blink | F26: 75 | G26: Pole Spin | H26: FE or I + Charge or Charge | I26: SUBTOTAL | K26: =SUM(J21:J25) -> 651 | L26: =K19+K26 -> 7904
A27: Armored Chest (firework) | B27: 500 | C27: DJ + Glide | D27: F | E27: Metal Chest in cave away from blink | F27: 25 | G27: Pole Spin | H27: N/A | I27: DRAGONFLY FALLS TOTAL | J27: =SUM(J5:J26) -> 7904
A28: Immediate (on ground + chests/baskets) ball gadget area | B28: 99 | C28: DJ + Glide | D28: N/A | E28: 3 Baskets above blink | F28: 75 | G28: Pole Spin | H28: N/A
A29: Armored Chest (firework) ball gadget area | B29: 500 | C29: DJ + Glide | D29: F | E29: SUBTOTAL | G29: =SUM(F22:F28) -> 1360 | H29: =G20+G29 -> 9045 | I29: missed 5 on test. Try again?
A30: 2 Huge Gnorc (armored) ball gadget area | B30: 40 | C30: DJ + Glide | D30: FE + Charge or I + Charge | E30: SWAMP TOTAL | F30: =SUM(F5:F29) -> 9045
A31: SUBTOTAL | C31: =SUM(B23:B30) -> 1670 | D31: =D21+C31 -> 4923
A32: DVCharge | E32: DRAGON KINGDOM TOTAL | F32: =B37+F30+J27 -> 22722
A33: Immediate (on ground + baskets + chests) | B33: 310 | C33: DJ + Charge | D33: N/A
A34: 2 Gnorc Archers | B34: =4973-4933 -> 40 | C34: DJ + Charge | D34: FE or I + Charge or Charge
A35: armored chest (firework) in byrd area | B35: 500 | C35: DJ + Charge | D35: F + Glide
A36: SUBTOTAL | C36: =SUM(B33:B35) -> 850 | D36: =D31+C36 -> 5773
A37: DRAGON VILLAGE TOTAL | B37: =SUM(B2:B35) -> 5773

Sheet Lost Cities EDITING
A1: ="Lost Cities (total " & F33 & ")" -> Lost Cities (total 34648)
A2: Coastal Remains (requires access card) | E2: Cloudy Domain (requires DJ + Glide) | I2: Sunken Ruins (requires DJ + Pole Spin)
A3: Description | B3: Amount | C3: Region Reqs | D3: Individual Reqs | E3: Description | F3: Amount | G3: Region Reqs | H3: Individual Reqs | I3: Description | J3: Amount | K3: Region Reqs | L3: Individual Reqs
A4: CREntry | E4: CDEntry | I4: SREntry
A5: On ground | B5: 722 | C5: N/A | D5: N/A | E5: On ground + baskets + chests + dark shards | F5: 507 | G5: N/A | H5: N/A | I5: On ground + chests + baskets + shards | J5: 240 | K5: N/A | L5: N/A
A6: Baskets | B6: 750 | C6: N/A | D6: FEWI or Charge or DJ | E6: Middle Gnorcs (flying) + Small Gnorcs (flying) | F6: 125 | G6: N/A | H6: FE | I6: Critters, Mer-Gnorc | J6: 125 | K6: N/A | L6: FE or I + Charge or Charge
A7: Metal Crates | B7: =350-75 -> 275 | C7: N/A | D7: E or Charge or DJ | E7: Huge Gnorcs (unarmored) | F7: 80 | G7: N/A | H7: FE or I + Charge | I7: SUBTOTAL | K7: =J5+J6 -> 365
A8: Headbash Crates | B8: 200 | C8: N/A | D8: DJ | E8: Middle Gnorcs (armored) | F8: 20 | G8: N/A | H8: FE + Charge or I + Charge or Charge | I8: SRSwim
A9: Large blue crabs | B9: 175 | C9: N/A | D9: E or I + Charge or Charge + DJ | E9: SUBTOTAL | G9: =SUM(F5:F8) -> 732 | I9: first swim Immediate underwater | J9: 15 | K9: Swim | L9: N/A
A10: Huge Gnorcs (armored) | B10: 60 | C10: N/A | D10: FE + Charge or I + Charge | E10: CDCharge | I10: first swim Underwater stuff (mer-gnorcs, vases, clams) | J10: 225 | K10: Swim | L10: Charge
A11: Huge Gnorc (unarmored) on way to Otto's pool | B11: 20 | C11: N/A | D11: FE or I + Charge | E11: Metal Chests behind Supercharge Door | F11: 75 | G11: Charge + Supercharge | H11: N/A | I11: after first swim immediate | J11: 579 | K11: Swim | L11: N/A
A12: Middle Gnorcs (unarmored) + Critters + Pygmy Cannibals + orange crabs | B12: =765-175 -> 590 | C12: N/A | D12: FE or I + Charge or Charge | E12: 3 Armored Chests before Elder | F12: 1500 | G12: Charge + Supercharge | H12: N/A | I12: after first swim Mer-Gnorc | J12: 25 | K12: Swim | L12: FE or I + Charge or Charge
A13: Crabs in Otto's Pool | B13: 175 | C13: Swim | D13: Charge | E13: on ground + Baskets + chests + dark shards | F13: 730 | G13: Charge | H13: N/A | I13: after first swim Immediates up the whirlwinds | J13: 397 | K13: Swim + Glide | L13: N/A
A14: Metal Chests in Otto's Pool | B14: 75 | C14: Swim | D14: Charge | E14: Middle Gnorcs (flying) + Small Gnorcs (flying) | F14: 125 | G14: Charge | H14: FE | I14: after first swim Armored Chests (firework up the whirlwinds) | J14: 1500 | K14: Swim + Glide | L14: F
A15: Underwater vases in southern beach | B15: 100 | C15: Swim | D15: Charge | E15: Huge Gnorcs (armored) | F15: 20 | G15: Charge | H15: FE + Charge or I + Charge | I15: second swim Immediate underwater | J15: 76 | K15: Swim | L15: N/A
A16: Underwater vases + clams in pole spin area | B16: 300 | C16: Swim | D16: Charge | E16: Huge Gnorc (unarmored) | F16: 20 | G16: Charge | H16: FE or I + Charge | I16: second swim Underwater stuff (mer-gnorcs, vases, clams) | J16: 250 | K16: Swim | L16: Charge
A17: SUBTOTAL | C17: =SUM(B5:B16) -> 3442 | E17: Armored Chest (firework right before light gem) | F17: 500 | G17: Charge | H17: F | I17: after second swim Immediate | J17: =1793+125 -> 1918 | K17: Swim | L17: N/A
A18: CRDoubleJump | E18: SUBTOTAL | G18: =SUM(F11:F17) -> 2970 | H18: =G9+G18 -> 3702 | I18: after second swim Blue Crabs | J18: 50 | K18: Swim | L18: E or I + Charge or Charge + DJ
A19: Pygmy Cannibal (small) in mini pathway across piranha pool | B19: 25 | C19: DJ | D19: FE or I + Charge or Charge | E19: CDWingShield | I19: after second swim Mer-Gnorc, Critters | J19: 100 | K19: Swim | L19: FE or I + Charge or Charge
A20: Baskets + Crates in mini pathway across piranha pool | B20: 50 | C20: DJ | D20: N/A | E20: Immediates | F20: 1225 | G20: Charge + Wing Shield | H20: N/A | I20: after second swim Chest + Basket near light gem after invince section | J20: 50 | K20: Swim + Invincibility | L20: N/A
A21: Immediate near dragon egg across piranha pool | B21: 98 | C21: DJ | D21: N/A | E21: Small Gnorcs (flying) | F21: 475 | G21: Charge + Wing Shield | H21: FE | I21: invince wall kick 3 Armored Chests further below (firework up high) | J21: 1500 | K21: Swim + Wall Kick + Invincibility | L21: F
A22: pole spin area Huge Gnorc (unarmored) by Dark Gem | B22: 20 | C22: DJ | D22: FE or I + Charge | E22: Huge Gnorc (unarmored) | F22: 40 | G22: Charge + Wing Shield | H22: FE or I + Charge | I22: invince wall kick Mer-gnorcs | J22: 50 | K22: Swim + Wall Kick + Invincibility | L22: FE or I + Charge or Charge
A23: pole spin area 4 Armored Chests by Dark Gem | B23: 2000 | C23: DJ | D23: Glide | E23: Byrd 1 | F23: 200 | G23: Charge + Wing Shield | H23: N/A | I23: Sparx 1 | J23: 1114 | K23: Swim | L23: N/A
A24: pole spin area 2 Armored Chests by Egg | B24: 1000 | C24: DJ + Glide + Pole Spin | D24: N/A | E24: Byrd 2 | F24: 200 | G24: Charge + Wing Shield | H24: N/A | I24: Sparx 2 | J24: 1034 | K24: Swim | L24: N/A
A25: pole spin area 2 Baskets on the way to Egg | B25: 50 | C25: DJ + Glide + Pole Spin | D25: N/A | E25: SUBTOTAL | G25: =SUM(F20:F24) -> 2140 | H25: =H18+G25 -> 5842 | I25: SUBTOTAL | K25: =SUM(J9:J24) -> 8883 | L25: =K7+K25 -> 9248
A26: pole spin area On ground post-cannon door | B26: 20 | C26: DJ + Glide | D26: N/A | E26: CDBallGadget | I26: SRElectric
A27: pinwheel area immediates | B27: 525 | C27: DJ | D27: N/A | E27: Ball Gadget (dragon egg) | F27: 715 | G27: Charge + Wing Shield + Ball Gadget | H27: N/A | I27: Immediate | J27: 606 | K27: Swim + E | L27: N/A
A28: pinwheel area pygmy hut | B28: 25 | C28: DJ | D28: FE or I + Charge or Charge | E28: Ball Gadget (light gem) | F28: 100 | G28: Charge + Wing Shield + Ball Gadget | H28: N/A | I28: Dark Shards above Invince | J28: 150 | K28: Swim + E + Glide | L28: N/A
A29: SUBTOTAL | C29: =SUM(B19:B28) -> 3813 | D29: =C17+C29 -> 7255 | E29: Armored Chest at start (firework post-ball gadget) | F29: 500 | G29: Charge + Wing Shield + Ball Gadget | H29: F | I29: SUBTOTAL | K29: =J27+J28 -> 756 | L29: =L25+K29 -> 10004
A30: CRLightGemDoor | E30: SUBTOTAL | G30: =SUM(F27:F29) -> 1315 | H30: =H25+G30 -> 7157 | I30: SRInvincibility
A31: On Ground | B31: 239 | C31: Light Gems | D31: N/A | E31: CLOUDY DOMAIN TOTAL | F31: =SUM(F5:F30) -> 7157 | I31: Immediate | J31: =540+1701 -> 2241 | K31: Swim + E + Invince | L31: N/A
A32: Huge Gnorcs (armored) | B32: 20 | C32: Light Gems | D32: FE + Charge or I + Charge | I32: Immediate via gliding next to firework | J32: 208 | K32: Swim + E + Invince + Glide | L32: N/A
A33: Baskets | B33: 125 | C33: Light Gems | D33: FEWI or Charge or DJ | E33: LOST CITIES TOTAL | F33: =B60+F31+J38 -> 34648 | I33: 3 Armored Chests below (firework after dark gem) | J33: 1500 | K33: Swim + E + Invince | L33: F
A34: Headbash Crates | B34: 50 | C34: Light Gems | D34: DJ | I34: SUBTOTAL | K34: =SUM(J31:J33) -> 3949 | L34: =L29+K34 -> 13953
A35: Gnorc Archers + Middle Gnorcs (unarmored) | B35: 40 | C35: Light Gems | D35: FE or I + Charge or Charge | I35: SRGlide
A36: Metal Crates | B36: 50 | C36: Light Gems | D36: E or Charge or DJ | I36: Immediate | J36: =150+542 -> 692 | K36: Swim + E + Invince + Glide | L36: N/A
A37: Immediate (baskets + crates up high) | B37: 125 | C37: Light Gems + DJ | D37: N/A | I37: SUBTOTAL | K37: =J36 -> 692 | L37: =L34+K37 -> 14645
A38: Gnorc Archers up high | B38: 40 | C38: Light Gems + DJ | D38: FE or I + Charge or Charge | I38: SUNKEN RUINS TOTAL | J38: =SUM(J5:J37) -> 14645
A39: Huge Gnorc (armored) up high | B39: 20 | C39: Light Gems + DJ | D39: FE + Charge or I + Charge
A40: SUBTOTAL | C40: =SUM(B31:B39) -> 709 | D40: =D29+C40 -> 7964
...

Sheet Icy Wilderness EDITING
A1: ="Icy Wilderness (total " & F15 & ")" -> Icy Wilderness (total 35801)
A2: Frostbite Village (requires access card, later on requires return via Gloomy Glacier) | E2: Gloomy Glacier (requires DJ) | I2: Ice Citadel (requires DJ)
A3: Description | B3: Amount | C3: Region Reqs | D3: Individual Reqs | E3: Description | F3: Amount | G3: Region Reqs | H3: Individual Reqs | I3: Description | J3: Amount | K3: Region Reqs | L3: Individual Reqs
A4: FVEntry | E4: GGEntry | I4: ICEntry
A5: Baskets | B5: 25 | C5: N/A | D5: FEWI or Charge or DJ | E5: Everything lol | F5: 1813 | G5: N/A | H5: N/A | I5: Immediate | J5: 1073 | K5: N/A | L5: N/A
A6: Headbash Crates | B6: 80 | C6: N/A | D6: DJ | E6: Armored Chest a bit into cave section | F6: 500 | G6: N/A | H6: 1 Explode-y Arrow | I6: Steel Traps | J6: 200 | K6: N/A | L6: E or I + Charge
A7: SUBTOTAL | C7: =B5+B6 -> 105 | E7: Armored Chest in distance by bullseye you hit to open gate | F7: 500 | G7: N/A | H7: 1 Explode-y Arrow | I7: Middle gnorcs (unarmored) + Gnorc Archers | J7: 180 | K7: N/A | L7: FE or I + Charge or Charge
A8: FVEletric | E8: 4 Frozen Gems | F8: 400 | G8: N/A | H8: 1 Explode-y Arrow each (4 total) | I8: Middle gnorcs (armored) | J8: 80 | K8: N/A | L8: FE + Charge or I + Charge or Charge
A9: Immediate | B9: 415 | C9: E | D9: N/A | E9: 8 Steel Traps | F9: 200 | G9: N/A | H9: 1 Explode-y Arrow each (8 total) | I9: 3 Baskets you can't DJ to break | J9: 75 | K9: N/A | L9: FEWI or Charge
A10: Immediate (near light gem after floating platform) | B10: 130 | C10: EW + DJ | D10: N/A | E10: Sparx 1 | F10: 1143 | G10: N/A | H10: N/A | I10: Huge Gnorcs (armored) | J10: 20 | K10: N/A | L10: FE + Charge or I + Charge
A11: Eskimole under snowman | B11: 25 | C11: DJ | D11: N/A | E11: Sparx 2 | F11: 1075 | G11: N/A | H11: N/A | I11: Firework chest + 3 Armored chests (firework by water wheel) | J11: 1525 | K11: N/A | L11: F
A12: SUBTOTAL | C12: =SUM(B9:B11) -> 570 | D12: =C7+C12 -> 675 | E12: SUBTOTAL | G12: =SUM(F5:F11) -> 5631 | I12: SUBTOTAL | K12: =SUM(J5:J11) -> 3153
A13: FVDoubleJump | E13: GLOOMY GLACIER TOTAL | F13: =SUM(F5:F12) -> 5631 | I13: ICWater
A14: Immediate (on ground + Baskets + crates) | B14: 1036 | C14: DJ | D14: N/A | I14: Immediate | J14: 683 | K14: W | L14: N/A
A15: Huge Gnorc (armored) | B15: 100 | C15: DJ | D15: FE + Charge or I + Charge | E15: ICY WILDERNESS TOTAL | F15: =B59+F13+J43 -> 35801 | I15: Steel Traps | J15: 400 | K15: W | L15: E or I + Charge
A16: Eskimoles (small) | B16: 175 | C16: DJ | D16: FE or Charge | I16: Yeti + Middle gnorcs (unarmored) | J16: 60 | K16: W | L16: FE or I + Charge or Charge
A17: Middle Gnorcs (unarmored) | B17: 20 | C17: DJ | D17: FE or I + Charge or Charge | I17: Headbash rock thing behind chargeable wall | J17: 25 | K17: W + Charge | L17: N/A
A18: Middle Gnorcs (armored) | B18: 40 | C18: DJ | D18: FE + Charge or I + Charge or Charge | I18: Middle gnorcs (armored) | J18: 20 | K18: W | L18: FE + Charge or I + Charge or Charge
A19: Eskimoles on Ice | B19: 35 | C19: DJ | D19: FE or Charge | I19: Huge Gnorcs (armored) | J19: 20 | K19: W | L19: FE + Charge or I + Charge
A20: Baskets on Ice | B20: 50 | C20: DJ | D20: FEWI or Charge | I20: SUBTOTAL | K20: =SUM(J14:J19) -> 1208 | L20: =K12+K20 -> 4361 | M20: missing 5 on test
A21: Blink 1 | B21: 1906 | C21: DJ | D21: N/A | I21: ICWallKick
A22: Blink 2 | B22: 1931 | C22: DJ | D22: N/A | I22: Immediate | J22: =1822+253 -> 2075 | K22: W + Wall Kick | L22: N/A
A23: SUBTOTAL | C23: =SUM(B14:B22) -> 5293 | D23: =D12+C23 -> 5968 | I23: Gnorc Archer | J23: 40 | K23: W + Wall Kick | L23: FE or I + Charge or Charge
A24: FVWallKickBeforeGlacier | I24: Firework chest | J24: 50 | K24: W + Wall Kick | L24: F
A25: Immediate (on ground + baskets + chests) | B25: 271 | C25: DJ + Wall Kick | D25: N/A | I25: Huge Gnorc (armored) | J25: 80 | K25: W + Wall Kick | L25: FE + Charge or I + Charge
A26: Middle Gnorc (unarmored) | B26: 20 | C26: DJ + Wall Kick | D26: FE or I + Charge or Charge | I26: Steel Traps | J26: 225 | K26: W + Wall Kick | L26: E or I + Charge
A27: Huge Gnorc (armored) | B27: 20 | C27: DJ + Wall Kick | D27: FE + Charge or I + Charge | I27: Ice Monster | J27: =59871-59846 -> 25 | K27: W + Wall Kick | L27: FE
A28: gems behind chargeable wall | B28: 11 | C28: DJ + Wall Kick + Charge | D28: N/A | I28: Middle Gnorc (unarmored) + Yeti | J28: 201 | K28: W + Wall Kick | L28: FE or I + Charge or Charge
A29: immediate beyond big cannon ball thing | B29: 630 | C29: DJ + Wall Kick + Glide | D29: N/A | I29: Huge Gnorc (unarmored) | J29: 20 | K29: W + Wall Kick | L29: FE or I + Charge
A30: Eskimole on the small platform thing | B30: 25 | C30: DJ + Wall Kick + Glide | D30: FE or Charge | I30: 10 Armored chests (cannon after queen) | J30: 5000 | K30: W + Wall Kick | L30: N/A
A31: SUBTOTAL | C31: =SUM(B25:B30) -> 977 | D31: =D23+C31 -> 6945 | I31: Armored Chests (supercharge) | J31: 1500 | K31: W + Wall Kick | L31: Supercharge
A32: =_xlfn._LONGTEXT("---------------------------------------------------------------------------------------------------------------------------------------------------------------------------------------------------------------------------------------------------------------","---------------------") -> ------------------------------------------------------------------------------------------------------------------------------------------------------------------------------------------------------------------------------------------------------------------------------------ | I32: Immediates past supercharge doors (tunnels + door next to drawbridge) | J32: 615 | K32: W + Wall Kick + Supercharge | L32: N/A
A33: FVEntry2 | I33: Byrd 1 | J33: 800 | K33: W + Wall Kick | L33: N/A
A34: Immediates | B34: 553 | C34: DJ + W + Wall Kick + Supercharge | D34: N/A | I34: Byrd 2 | J34: 830 | K34: W + Wall Kick | L34: N/A
A35: Eskimoles | B35: 175 | C35: DJ + W + Wall Kick + Supercharge | D35: FE or Charge | I35: SUBTOTAL | K35: =SUM(J22:J34) -> 11461 | L35: =L20+K35 -> 15822
A36: 2 Armored Chests (cannon near light gem door) | B36: 1000 | C36: DJ + W + Wall Kick + Supercharge | D36: N/A | I36: ICBehindQueen
A37: Huge gnorc (armored) | B37: 20 | C37: DJ + W + Wall Kick + Supercharge | D37: FE + Charge or I + Charge | I37: Huge Gnorc (armored) | J37: 20 | K37: W + Wall Kick + E + Pole Spin | L37: FE + Charge or I + Charge
A38: SUBTOTAL | C38: =SUM(B34:B37) -> 1748 | I38: Gnorc Archer | J38: 60 | K38: W + Wall Kick + E + Pole Spin | L38: FE or I + Charge or Charge
A39: FVEastPoles | I39: SUBTOTAL | K39: =J37+J38 -> 80 | L39: =L35+K39 -> 15902
A40: Huge gnorc (armored) | B40: 20 | C40: DJ + W + Wall Kick + Charge + Supercharge + Pole Spin | D40: FE or I | I40: ICReturnToFV
...

Sheet Volcanic Isle EDITING
A1: ="Volcanic Isle (total " & F33 & ")" -> Volcanic Isle (total 49306)
A2: Stormy Beach (requires access card) | E2: Molten Mount (requires DJ + Glide) | I2: Magma Falls (requires DJ + Glide + WI + Pole Spin + Wall Kick) | M2: Dark Mine (requires DJ + Glide + WI + Pole Spin + Wall Kick + Ball Gadget) | Q2: Red's Lab (needs DJ + Glide + WI + Pole Spin + Wall Kick + Ball Gadget + charge + E + Ice)
A3: Description | B3: Amount | C3: Region Reqs | D3: Individual Reqs | E3: Description | F3: Amount | G3: Region Reqs | H3: Individual Reqs | I3: Description | J3: Amount | K3: Region Reqs | L3: Individual Reqs | M3: Description | N3: Amount | O3: Region Reqs | P3: Individual Reqs | Q3: Description | R3: Amount | S3: Region Reqs | T3: Individual Reqs
A4: SBEntry | E4: MMEntry | I4: MFtEntry | M4: DMEntry | Q4: RLEntry
A5: On ground | B5: 263 | C5: N/A | D5: N/A | E5: Immediate | F5: 572 | G5: N/A | H5: N/A | I5: Immediate | J5: =695+75 -> 770 | K5: N/A | L5: N/A | M5: Immediates | N5: =690+50 -> 740 | O5: N/A | P5: N/A | Q5: Immediates | R5: 1083 | S5: N/A | T5: N/A
A6: Baskets | B6: 350 | C6: N/A | D6: FEWI or Charge or DJ | E6: Steel traps | F6: 50 | G6: N/A | H6: E or I + Charge | I6: Metal chests behind chargeable thing | J6: 50 | K6: Charge | L6: N/A | M6: Critters | N6: 75 | O6: N/A | P6: FE or I + Charge or Charge | Q6: SUBTOTAL | S6: =R5 -> 1083
A7: Metal Chests | B7: 300 | C7: N/A | D7: E or Charge or DJ | E7: Armored chest near start (firework) | F7: 500 | G7: N/A | H7: F | I7: Middle gnorc (unarmored) | J7: 20 | K7: N/A | L7: FE or I + Charge or Charge | M7: Haywire Robots (Drill) | N7: 60 | O7: N/A | P7: E or I + Charge or Charge | Q7: RLSouthEast
A8: Headbash Chest | B8: 30 | C8: N/A | D8: DJ | E8: Armored chests near start (supercharge) | F8: 1500 | G8: N/A | H8: Supercharge | I8: Firework chest (immediate) | J8: 25 | K8: N/A | L8: F | M8: Immediates behind chargeable wall things | N8: 100 | O8: Charge | P8: N/A | Q8: Immediates | R8: 680 | S8: N/A | T8: N/A
A9: Dark Shards | B9: 350 | C9: N/A | D9: Charge or DJ | E9: SUBTOTAL | G9: =SUM(F5:F8) -> 2622 | I9: Firework chest (behind chargeable thing) | J9: 25 | K9: Charge | L9: F | M9: Haywire Robots (Spike) | N9: 50 | O9: N/A | P9: E or I + Charge | Q9: Immediates above furnace | R9: 70 | S9: F | T9: N/A
A10: Steel Traps | B10: 375 | C10: N/A | D10: E or I + Charge | E10: MMFireEnemies | I10: Rock monster | J10: 100 | K10: N/A | L10: Charge | M10: Steel Traps | N10: 100 | O10: N/A | P10: E or I + Charge | Q10: SUBTOTAL | S10: =R8+R9 -> 750 | T10: =S6+S10 -> 1833
A11: 2 Armored Chests (firework on the ship) | B11: 1000 | C11: N/A | D11: F | E11: initial gliding 2 Phoenixes | F11: 50 | G11: WI | H11: N/A | I11: Armored chest (firework) | J11: 500 | K11: N/A | L11: F | M11: SUBTOTAL | O11: =SUM(N5:N10) -> 1125 | Q11: RLNorthWest
A12: Middle Gnorcs (unarmored) | B12: 140 | C12: N/A | D12: FE or I + Charge or Charge | E12: initial gliding Immediates while jumping up | F12: 131 | G12: WI | H12: N/A | I12: Immediates behind chargeable thing by moneybags | J12: 50 | K12: Charge | L12: N/A | M12: DMLightGemDoor | Q12: Immediates | R12: 1119 | S12: N/A | T12: N/A
A13: Middle gnorcs (armored) | B13: 80 | C13: N/A | D13: FE + Charge or I + Charge or Charge | E13: initial gliding Firework Chest | F13: 25 | G13: WI | H13: F | I13: Huge gnorc (armored) behind chargeable thing by moneybags | J13: 20 | K13: Charge | L13: FE + Charge or I + Charge | M13: Huge robo-gnorcs | N13: 470 | O13: Light Gems | P13: E or I + Charge | Q13: SUBTOTAL | S13: =R12 -> 1119 | T13: =T10+S13 -> 2952
A14: Huge Gnorcs (armored) | B14: 60 | C14: N/A | D14: FE + Charge or I + Charge | E14: Immediates | F14: 1548 | G14: WI | H14: N/A | I14: Huge gnorcs (armored) by ball gadget | J14: 40 | K14: N/A | L14: FE + Charge or I + Charge | M14: Critters | N14: 125 | O14: Light Gems | P14: FE or I + Charge or Charge | Q14: RLNorthEast
A15: Underwater vases by realm portal | B15: 100 | C15: Swim | D15: Charge | E15: Rock Monsters | F15: 400 | G15: WI | H15: Charge | I15: SUBTOTAL | K15: =SUM(J5:J14) -> 1600 | M15: Steel Traps | N15: 50 | O15: Light Gems | P15: E or I + Charge | Q15: Immediates | R15: =109265-108705 -> 560 | S15: N/A | T15: N/A
A16: SUBTOTAL | C16: =SUM(B5:B15) -> 3048 | E16: Huge gnorcs (armored) | F16: 40 | G16: WI | H16: FE + Charge or I + Charge | I16: MFBallGadget | M16: Invince swimming (chests) | N16: 350 | O16: Light Gems + Invince | P16: Charge | Q16: Immediates via invince | R16: 155 | S16: Invincibility | T16: N/A
A17: SBDoubleJump | E17: Huge gnorcs (unarmored) | F17: 20 | G17: WI | H17: FE or I + Charge | I17: Immediates | J17: 447 | K17: Ball Gadget | L17: N/A | M17: SUBTOTAL | O17: =SUM(N13:N16) -> 995 | P17: =O11+O17 -> 2120 | Q17: SUBTOTAL | S17: =R15+R16 -> 715 | T17: =T13+S17 -> 3667
A18: Immediate | B18: =1334+80 -> 1414 | C18: DJ | D18: N/A | E18: middle gnorcs (unarmored) | F18: 20 | G18: WI | H18: FE or I + Charge or Charge | I18: SUBTOTAL | K18: =J17 -> 447 | L18: =K15+K18 -> 2047 | M18: DMCharge | Q18: RLSouthWest
A19: 3 armored chests near shop (firework on ground level) | B19: 1500 | C19: DJ | D19: F | E19: Byrd 1 | F19: 443 | G19: WI | H19: N/A | I19: MFbEntry | M19: 3 armored chests (firework) | N19: 1500 | O19: Charge | P19: F | Q19: Immediates | R19: 140
A20: Huge Gnorcs (armored) | B20: 20 | C20: DJ | D20: FE + Charge or I + Charge | E20: Byrd 2 | F20: 443 | G20: WI | H20: N/A | I20: Immediates | J20: 1101 | K20: Ball Gadget | L20: N/A | M20: Immediate | N20: 550 | O20: Charge | P20: N/A | Q20: SUBTOTAL | S20: =R19 -> 140 | T20: =T17+S20 -> 3807
A21: Gnorc archers | B21: 20 | C21: DJ | D21: FE or I + Charge or Charge | E21: SUBTOTAL | G21: =SUM(F11:F20) -> 3120 | H21: =G9+G21 -> 5742 | I21: Middle gnorc (armored) | J21: 60 | K21: Ball Gadget | L21: FE + Charge or I + Charge or Charge | M21: Huge robo-gnorcs | N21: 20 | O21: Charge | P21: E or I + Charge | Q21: RED'S LAB TOTAL | R21: =SUM(R5:R19) -> 3807
A22: Middle gnorc (armored) | B22: 20 | C22: DJ | D22: FE + Charge or I + Charge or Charge | E22: MMPoleSpin | I22: Middle gnorc (armored) | J22: 60 | K22: Ball Gadget | L22: FE + Charge or I + Charge or Charge | M22: Immediates up wall kick pistons | N22: 70 | O22: Charge + Wall Kick | P22: N/A
A23: Middle gnorcs (unarmored) | B23: 20 | C23: DJ | D23: FE or I + Charge or Charge | E23: headbash rock thing under huge gnorc (unarmored) | F23: 25 | G23: WI + Pole Spin | H23: FE or I + Charge | I23: Huge gnorc (armored) | J23: 40 | K23: Ball Gadget | L23: FE + Charge or I + Charge | M23: SUBTOTAL | O23: =SUM(N19:N22) -> 2140 | P23: =P17+O23 -> 4260
A24: 2 armored chests (firework inside cave) | B24: 1000 | C24: DJ | D24: F | E24: Immediates | F24: 5131 | G24: WI + Pole Spin | H24: N/A | I24: Huge gnorc (unarmored) | K24: Ball Gadget | L24: FE or I + Charge | M24: DMElectric
A25: SUBTOTAL | C25: =SUM(B18:B24) -> 3994 | D25: =C16+C25 -> 7042 | E25: Middle gnorc (unarmored) | F25: 260 | G25: WI + Pole Spin | H25: FE or I + Charge or Charge | I25: Metal chests behind chargeable things | J25: 25 | K25: Ball Gadget + Charge | L25: N/A | M25: Immediates | N25: 1240 | O25: Charge + E | P25: N/A
A26: SBUpperCave | E26: Middle gnorc (armored) | F26: 40 | G26: WI + Pole Spin | H26: FE + Charge or I + Charge or Charge | I26: Immediates behind Chargeable wall near end | J26: 311 | K26: Ball Gadget + Charge | L26: N/A | M26: Blink 1 | N26: 5240 | O26: Charge + E | P26: N/A
A27: Gnorc archers by chest | B27: 40 | C27: DJ + Wall Kick + Glide | D27: FE or I + Charge or Charge | E27: Huge gnorc (armored) | F27: 60 | G27: WI + Pole Spin | H27: FE + Charge or I + Charge | I27: Sparx 1 | J27: 1313 | K27: Ball Gadget | L27: N/A | M27: Blink 2 | N27: 6980 | O27: Charge + E | P27: N/A
A28: Immediate | B28: 60 | C28: DJ + Wall Kick + Glide | D28: N/A | E28: Glitchy headbash thing heading north to dark gem in upper area | F28: 25 | G28: WI + Pole Spin | H28: N/A | I28: Sparx 2 | J28: 1076 | K28: Ball Gadget | L28: N/A | M28: SUBTOTAL | O28: =N27 -> 6980 | P28: =P23+O28 -> 11240
A29: SUBTOTAL | C29: =B27+B28 -> 100 | D29: =D25+C29 -> 7142 | E29: Immediates behind chargeable walls near end | F29: =110+780 -> 890 | G29: WI + Pole Spin + Charge | H29: N/A | I29: SUBTOTAL | K29: =SUM(J20:J28) -> 3986 | L29: =L18+K29 -> 6033 | M29: DMIce
A30: STORMY BEACH TOTAL | B30: =SUM(B5:B28) -> 7142 | E30: SUBTOTAL | G30: =SUM(F23:F29) -> 6431 | H30: =H21+G30 -> 12173 | I30: MAGMA FALLS TOTAL | J30: =SUM(J5:J29) -> 6033 | M30: Immediates | N30: =795+136 -> 931 | O30: Charge + E + Ice
E31: MOLTEN MOUNT TOTAL | F31: =SUM(F5:F29) -> 12173 | M31: 3 armored chests by start (firework after ice and pole spin) | N31: 1500 | O31: Charge + E + Ice | P31: F
M32: SUBTOTAL | O32: =N30+N31 -> 2431 | P32: =P28+O32 -> 13671
E33: VOLCANIC ISLE TOTAL | F33: =B30+F31+J30+N33+R21 -> 49306 | M33: DARK MINE TOTAL | N33: =SUM(N4:N32) -> 20151
E35: GAME TOTAL | F35: ='Dragon Kingdom'!F36+'Lost Cities'!F32+'Icy Wilderness'!F16+'Volcanic Isle EDITING'!F33 -> 139488

Sheet Dragon Kingdom
A1: ="Dragon Kingdom (total " & F36 & ")" -> Dragon Kingdom (total 21947)
A2: Dragon Village (needs access card) | E2: Crocoville Swamp (needs DJ) | I2: Dragonfly Falls (needs DJ + Glide + Ball Gadget)
A3: Description | B3: Amount | C3: Region Reqs | D3: Individual Reqs | E3: Description | F3: Amount | G3: Region Reqs | H3: Individual Reqs | I3: Description | J3: Amount | K3: Region Reqs | L3: Individual Reqs
A4: Starting Area | E4: Immediate Access | I4: Immediate Access
A5: Immediate (on ground) | B5: 336 | C5: N/A | D5: None | E5: Immediate (on ground + chests + baskets + dark shards) | F5: 873 | G5: N/A | H5: N/A | I5: Ball Gadget Path | J5: 896 | K5: N/A | L5: N/A
A6: Baskets | B6: 175 | C6: N/A | D6: FEWI or Charge or DJ | E6: Crocoviles + Critters | F6: 345 | G6: N/A | H6: FE or I + Charge or Charge | I6: Crocoviles + Shepherd | J6: 395 | K6: N/A | L6: FE or I + Charge or Charge
A7: Metal Chests | B7: 100 | C7: N/A | D7: E or Charge or DJ | E7: Plants + Huge Gnorcs (unarmored) | F7: 161 | G7: N/A | H7: FE or I + Charge | I7: Immediate (on ground + Chests + Baskets) | J7: 1511 | K7: N/A | L7: N/A
A8: Dark Shards | B8: 300 | C8: N/A | D8: Charge or DJ | E8: 3 Baskets behind chargeable thing | F8: 75 | G8: Charge | H8: N/A | I8: 3 Goats | J8: 75 | K8: N/A | L8: FE
A9: Breakable Wall Near Elder | E9: Metal Chest behind chargeable thing in Elder's tree | F9: 25 | G9: Charge | H9: N/A | I9: Plant + Huge Gnorcs (unarmored) | J9: 55 | K9: N/A | L9: FE or I + Charge
A10: Baskets | B10: 150 | C10: Charge | D10: N/A | E10: 2 Armored Chests on pyramid (cannon) | F10: 1000 | G10: N/A | H10: Glide | I10: Huge Gnorcs (armored) | J10: 100 | K10: N/A | L10: FE + Charge or I + Charge
A11: Hunter Area Pre-Glide | E11: 5 Armored Chests (supercharge) | F11: 2500 | G11: N/A | H11: Supercharge | I11: Underwater in Piranha Area | J11: 100 | K11: Swim | L11: Charge
A12: On Ground | B12: 31 | C12: DJ | D12: N/A | E12: 2 metal chests behind supercharge door | F12: 50 | G12: Supercharge | H12: N/A | I12: Chargeable Walls
A13: Chests/Baskets | B13: 280 | C13: DJ | D13: N/A | E13: Armored Chest (firework in area after pyramid dark gem) | F13: 500 | G13: N/A | H13: F | I13: 5 Dark Shards behind chargeable wall with dark gem | J13: 250 | K13: Charge | L13: N/A
A14: 2 Huge Gnorcs (unarmored) | B14: 40 | C14: DJ | D14: FE or Ice + Charge | E14: Mini Pyramid (Crocovile Gate) | I14: Chests + Baskets behind chargeable walls | J14: 899 | K14: Charge | L14: N/A
A15: Hunter Area Post-Glide | E15: Crocovile | F15: 25 | G15: N/A | H15: FE or I + Charge or Charge | I15: Light Gem Door
A16: Immediate (on ground + chests/baskets) | B16: 426 | C16: DJ & Glide | D16: N/A | E16: Baskets + Chests behind gate | F16: 80 | G16: N/A | H16: N/A | I16: Immediate (on ground + chests + baskets) | J16: 289 | K16: Light Gems | L16: N/A
A17: Middle Gnorc (unarmored) in room | B17: 20 | C17: DJ & Glide | D17: FE or I + Charge or Charge | E17: Mini Pyramid (Electric Gate) | I17: Huge Gnorcs (unarmored) | J17: 60 | K17: Light Gems | L17: FE or I + Charge
A18: Huge Gnorc (unarmored) outside | B18: 20 | C18: DJ & Glide | D18: FE or I + Charge | E18: Crocoviles | F18: 70 | G18: E | H18: FE or I + Charge or Charge | I18: Huge Gnorcs (armored) | J18: 40 | K18: Light Gems | L18: FE + Charge or I + Charge
A19: Huge Gnorc (armored) in cave | B19: 20 | C19: DJ & Glide | D19: FE + Charge or I + Charge | E19: Chests + Baskets | F19: 175 | G19: E | H19: N/A | I19: Blue Monkeys | J19: 75 | K19: Light Gems | L19: FE or I + Charge or Charge
A20: Armored Chest (firework) | B20: 500 | C20: DJ & Glide | D20: F | E20: Pole Spinning in Elder's Tree area | I20: Below whirlwind behind chargeable wall | J20: 187 | K20: Light Gems | L20: N/A
A21: Ball Gadget Area (post-Hunter) | E21: Baskets + Chests | F21: 160 | G21: Pole Spin | H21: N/A | I21: Hunter Section
A22: Immediate (on ground + chests/baskets) | B22: 99 | C22: DJ & Glide | D22: N/A | E22: Crocovile | F22: 25 | G22: Pole Spin | H22: FE or I + Charge or Charge | I22: Immediate (almost everything) | J22: =1166+90 -> 1256 | K22: N/A | L22: N/A
A23: Armored Chest (firework) | B23: 500 | C23: DJ & Glide | D23: F | E23: Armored Chest (firework at top of tree) | F23: 500 | G23: Pole Spin | H23: F | I23: Behind first explode-y arrow wall | J23: 143 | K23: N/A | L23: 1 Explosive Arrow
A24: 2 Huge Gnorc (armored) | B24: 40 | C24: DJ & Glide | D24: FE + Charge or I + Charge | E24: Armored Chest (firework at middle of tree) | F24: 500 | G24: Pole Spin + Charge or Glide | H24: F | I24: 2 Metal chests in distance | J24: 50 | K24: N/A | L24: 1 Explosive Arrow
A25: Post-Dark Gem by Ember | E25: Cave via Pole Spinning a bit away from Blink | I25: Sparx
A26: Armored Chest before bridge (firework) | B26: 500 | C26: DJ | D26: F | E26: Crocoviles | F26: 75 | G26: Pole Spin | H26: FE or I + Charge or Charge | I26: Sparx 1 | J26: 695 | K26: N/A | L26: N/A
A27: Immediate (on ground + baskets) | B27: 215 | C27: DJ | D27: N/A | E27: Metal Chest | F27: 25 | G27: Pole Spin | H27: N/A | I27: Sparx 2 | J27: 828 | K27: N/A | L27: N/A
A28: Post-Double Jump Ledge Next to Lab | E28: Pole Spinning above Blink
